Workbook

Sheet Insights
A1: Key Findings & Recommendations
A2: Findings below are formulas, so the numbers update if the data or settings change. Recommendations are analyst judgement.
A4: Findings
A5: ="1. Overall: the cohort averages "&TEXT(Analysis!B6,"0.0")&" and "&TEXT(Analysis!B7,"0.0%")&" of students pass (pass mark "&Settings!B3&")." -> 1. Overall: the cohort averages 61.6 and 89.0% of students pass (pass mark 50).
A6: ="2. Subjects: "&Dashboard!P5&" is the weakest subject and "&Dashboard!M5&" the strongest (averages "&TEXT(MIN(Analysis!B18:B22),"0.0")&" and "&TEXT(MAX(Analysis!B18:B22),"0.0")&")." -> 2. Subjects: Science is the weakest subject and Social_Studies the strongest (averages 61.3 and 62.0).
A7: ="3. Study time: students in the "&Analysis!A70&" band average "&TEXT(Analysis!C70,"0.0")&", versus "&TEXT(Analysis!C66,"0.0")&" for the "&Analysis!A66&" band (r = "&TEXT(Analysis!B91,"0.00")&", "&LOWER(Analysis!C91)&")." -> 3. Study time: students in the 20+ hrs band average 74.4, versus 50.0 for the 0 to 4 hrs band (r = 0.68, strong).
A8: ="4. Attendance: the "&Analysis!A78&" band averages "&TEXT(Analysis!C78,"0.0")&" versus "&TEXT(Analysis!C75,"0.0")&" for "&Analysis!A75&" (r = "&TEXT(Analysis!B92,"0.00")&", "&LOWER(Analysis!C92)&")." -> 4. Attendance: the 95 to 100% band averages 66.1 versus 55.1 for Below 75% (r = 0.40, moderate).
A9: ="5. Gender: females lead English by "&TEXT(Analysis!D27,"0.0")&" points; males lead Math by "&TEXT(-Analysis!D26,"0.0")&" points. Overall averages are "&TEXT(Analysis!C34,"0.0")&" (F) and "&TEXT(Analysis!C35,"0.0")&" (M)." -> 5. Gender: females lead English by 4.5 points; males lead Math by 2.6 points. Overall averages are 61.6 (F) and 61.6 (M).
A10: ="6. Home support: students with internet access average "&TEXT(Analysis!C54,"0.0")&" versus "&TEXT(Analysis!C55,"0.0")&" without; tertiary-educated parents: "&TEXT(Analysis!C49,"0.0")&" vs "&TEXT(Analysis!C47,"0.0")&" for basic." -> 6. Home support: students with internet access average 62.9 versus 59.0 without; tertiary-educated parents: 63.9 vs 58.7 for basic.
A11: ="7. Risk: "&Analysis!B12&" students ("&TEXT(Analysis!B13,"0.0%")&") are flagged at-risk (average below "&Settings!B4&" or attendance below "&Settings!B5&"%)." -> 7. Risk: 92 students (30.7%) are flagged at-risk (average below 55 or attendance below 75%).
A13: Recommendations (analyst judgement, based on the patterns above)
A14: A. Offer structured study support (supervised study periods, peer groups) for students in the lowest study-hours band.
A15: B. Trigger an attendance early-warning check when a student drops under the attendance threshold on the Settings sheet.
A16: C. Review teaching support in the weakest subject shown on the Dashboard; compare results across classes before drawing conclusions.
A17: D. Look at access gaps: a school computer lab / library hours could help students without home internet.
A18: E. Use the At_Risk filter on the Data sheet to build a named intervention list for counsellors and class teachers.
A20: Limitations
A21: - The data is synthetic (generated with a fixed random seed), so findings demonstrate method, not real-school facts.
A22: - Correlation is not causation; study hours and attendance may both reflect motivation or home circumstances.
A23: - Averages treat all five subjects equally; a school with weighted subjects would change the Average formula.

Sheet Dashboard
A1: Student Performance Dashboard
A2: 300 students | 5 subjects | Source: synthetic dataset (see README)
A4: STUDENTS | D4: AVERAGE SCORE | G4: PASS RATE | J4: AT-RISK STUDENTS | M4: STRONGEST SUBJECT | P4: WEAKEST SUBJECT
A5: =Analysis!B5 -> 300 | D5: =Analysis!B6 -> 61.601333 | G5: =Analysis!B7 -> 0.89 | J5: =Analysis!B12 -> 92 | M5: =INDEX(Analysis!A18:A22,MATCH(MAX(Analysis!B18:B22),Analysis!B18:B22,0)) -> Social_Studies | P5: =INDEX(Analysis!A18:A22,MATCH(MIN(Analysis!B18:B22),Analysis!B18:B22,0)) -> Science

Sheet Analysis
A1: Analysis Tables
A2: Every figure is a live formula on the Data sheet (COUNTIFS / AVERAGEIFS / CORREL).
A4: 1. Key performance indicators
A5: Total students | B5: =COUNTA(Data!$A$2:$A$301) -> 300
A6: Overall average score | B6: =AVERAGE(Data!$N$2:$N$301) -> 61.601333
A7: Pass rate | B7: =COUNTIF(Data!$P$2:$P$301,"Pass")/COUNTA(Data!$A$2:$A$301) -> 0.89
A8: Median average score | B8: =MEDIAN(Data!$N$2:$N$301) -> 62.1
A9: Std deviation of average | B9: =STDEV(Data!$N$2:$N$301) -> 9.4879468
A10: Highest student average | B10: =MAX(Data!$N$2:$N$301) -> 88.6
A11: Lowest student average | B11: =MIN(Data!$N$2:$N$301) -> 32.2
A12: At-risk students | B12: =COUNTIF(Data!$S$2:$S$301,"Yes") -> 92
A13: At-risk share | B13: =B12/B5 -> 0.30666667
A16: 2. Subject performance
A17: Subject | B17: Average | C17: Highest | D17: Lowest | E17: Pass rate (>= pass mark)
A18: Math | B18: =AVERAGE(Data!$I$2:$I$301) -> 61.656667 | C18: =MAX(Data!$I$2:$I$301) -> 100 | D18: =MIN(Data!$I$2:$I$301) -> 31 | E18: =COUNTIF(Data!$I$2:$I$301,">="&Settings!$B$3)/COUNT(Data!$I$2:$I$301) -> 0.84333333
A19: English | B19: =AVERAGE(Data!$J$2:$J$301) -> 61.726667 | C19: =MAX(Data!$J$2:$J$301) -> 93 | D19: =MIN(Data!$J$2:$J$301) -> 26 | E19: =COUNTIF(Data!$J$2:$J$301,">="&Settings!$B$3)/COUNT(Data!$J$2:$J$301) -> 0.88666667
A20: Science | B20: =AVERAGE(Data!$K$2:$K$301) -> 61.253333 | C20: =MAX(Data!$K$2:$K$301) -> 93 | D20: =MIN(Data!$K$2:$K$301) -> 30 | E20: =COUNTIF(Data!$K$2:$K$301,">="&Settings!$B$3)/COUNT(Data!$K$2:$K$301) -> 0.86333333
A21: Social_Studies | B21: =AVERAGE(Data!$L$2:$L$301) -> 62.006667 | C21: =MAX(Data!$L$2:$L$301) -> 90 | D21: =MIN(Data!$L$2:$L$301) -> 31 | E21: =COUNTIF(Data!$L$2:$L$301,">="&Settings!$B$3)/COUNT(Data!$L$2:$L$301) -> 0.86
A22: ICT | B22: =AVERAGE(Data!$M$2:$M$301) -> 61.363333 | C22: =MAX(Data!$M$2:$M$301) -> 88 | D22: =MIN(Data!$M$2:$M$301) -> 22 | E22: =COUNTIF(Data!$M$2:$M$301,">="&Settings!$B$3)/COUNT(Data!$M$2:$M$301) -> 0.85333333
A24: 3. Subject average by gender
A25: Subject | B25: Female | C25: Male | D25: Gap (F - M)
A26: Math | B26: =AVERAGEIFS(Data!$I$2:$I$301,Data!$B$2:$B$301,B$25) -> 60.459627 | C26: =AVERAGEIFS(Data!$I$2:$I$301,Data!$B$2:$B$301,C$25) -> 63.043165 | D26: =B26-C26 -> -2.5835381
A27: English | B27: =AVERAGEIFS(Data!$J$2:$J$301,Data!$B$2:$B$301,B$25) -> 63.813665 | C27: =AVERAGEIFS(Data!$J$2:$J$301,Data!$B$2:$B$301,C$25) -> 59.309353 | D27: =B27-C27 -> 4.5043121
A28: Science | B28: =AVERAGEIFS(Data!$K$2:$K$301,Data!$B$2:$B$301,B$25) -> 60.78882 | C28: =AVERAGEIFS(Data!$K$2:$K$301,Data!$B$2:$B$301,C$25) -> 61.791367 | D28: =B28-C28 -> -1.002547
A29: Social_Studies | B29: =AVERAGEIFS(Data!$L$2:$L$301,Data!$B$2:$B$301,B$25) -> 62.329193 | C29: =AVERAGEIFS(Data!$L$2:$L$301,Data!$B$2:$B$301,C$25) -> 61.633094 | D29: =B29-C29 -> 0.69609902
A30: ICT | B30: =AVERAGEIFS(Data!$M$2:$M$301,Data!$B$2:$B$301,B$25) -> 60.73913 | C30: =AVERAGEIFS(Data!$M$2:$M$301,Data!$B$2:$B$301,C$25) -> 62.086331 | D30: =B30-C30 -> -1.3472005
A32: 4. Performance by gender
A33: Gender | B33: Students | C33: Avg score | D33: Pass rate | E33: Avg study hrs/wk | F33: Avg attendance %
A34: Female | B34: =COUNTIFS(Data!$B$2:$B$301,$A34) -> 161 | C34: =IFERROR(AVERAGEIFS(Data!$N$2:$N$301,Data!$B$2:$B$301,$A34),0) -> 61.626087 | D34: =IFERROR(COUNTIFS(Data!$B$2:$B$301,$A34,Data!$P$2:$P$301,"Pass")/B34,0) -> 0.89440994 | E34: =IFERROR(AVERAGEIFS(Data!$D$2:$D$301,Data!$B$2:$B$301,$A34),0) -> 11.198758 | F34: =IFERROR(AVERAGEIFS(Data!$E$2:$E$301,Data!$B$2:$B$301,$A34),0) -> 84.937888
A35: Male | B35: =COUNTIFS(Data!$B$2:$B$301,$A35) -> 139 | C35: =IFERROR(AVERAGEIFS(Data!$N$2:$N$301,Data!$B$2:$B$301,$A35),0) -> 61.572662 | D35: =IFERROR(COUNTIFS(Data!$B$2:$B$301,$A35,Data!$P$2:$P$301,"Pass")/B35,0) -> 0.88489209 | E35: =IFERROR(AVERAGEIFS(Data!$D$2:$D$301,Data!$B$2:$B$301,$A35),0) -> 11.389928 | F35: =IFERROR(AVERAGEIFS(Data!$E$2:$E$301,Data!$B$2:$B$301,$A35),0) -> 84.172662
A36: Total / overall | B36: =SUM(B34:B35) -> 300 | C36: =AVERAGE(Data!$N$2:$N$301) -> 61.601333 | D36: =COUNTIF(Data!$P$2:$P$301,"Pass")/COUNTA(Data!$A$2:$A$301) -> 0.89 | E36: =AVERAGE(Data!$D$2:$D$301) -> 11.287333 | F36: =AVERAGE(Data!$E$2:$E$301) -> 84.583333
A38: 5. Performance by grade level
A39: Grade Level | B39: Students | C39: Avg score | D39: Pass rate | E39: Avg study hrs/wk | F39: Avg attendance %
A40: Grade 10 | B40: =COUNTIFS(Data!$C$2:$C$301,$A40) -> 101 | C40: =IFERROR(AVERAGEIFS(Data!$N$2:$N$301,Data!$C$2:$C$301,$A40),0) -> 61.338614 | D40: =IFERROR(COUNTIFS(Data!$C$2:$C$301,$A40,Data!$P$2:$P$301,"Pass")/B40,0) -> 0.91089109 | E40: =IFERROR(AVERAGEIFS(Data!$D$2:$D$301,Data!$C$2:$C$301,$A40),0) -> 11.086139 | F40: =IFERROR(AVERAGEIFS(Data!$E$2:$E$301,Data!$C$2:$C$301,$A40),0) -> 85.059406
A41: Grade 11 | B41: =COUNTIFS(Data!$C$2:$C$301,$A41) -> 111 | C41: =IFERROR(AVERAGEIFS(Data!$N$2:$N$301,Data!$C$2:$C$301,$A41),0) -> 61.153153 | D41: =IFERROR(COUNTIFS(Data!$C$2:$C$301,$A41,Data!$P$2:$P$301,"Pass")/B41,0) -> 0.86486486 | E41: =IFERROR(AVERAGEIFS(Data!$D$2:$D$301,Data!$C$2:$C$301,$A41),0) -> 11.227027 | F41: =IFERROR(AVERAGEIFS(Data!$E$2:$E$301,Data!$C$2:$C$301,$A41),0) -> 83.72973
A42: Grade 12 | B42: =COUNTIFS(Data!$C$2:$C$301,$A42) -> 88 | C42: =IFERROR(AVERAGEIFS(Data!$N$2:$N$301,Data!$C$2:$C$301,$A42),0) -> 62.468182 | D42: =IFERROR(COUNTIFS(Data!$C$2:$C$301,$A42,Data!$P$2:$P$301,"Pass")/B42,0) -> 0.89772727 | E42: =IFERROR(AVERAGEIFS(Data!$D$2:$D$301,Data!$C$2:$C$301,$A42),0) -> 11.594318 | F42: =IFERROR(AVERAGEIFS(Data!$E$2:$E$301,Data!$C$2:$C$301,$A42),0) -> 85.113636
A43: Total / overall | B43: =SUM(B40:B42) -> 300 | C43: =AVERAGE(Data!$N$2:$N$301) -> 61.601333 | D43: =COUNTIF(Data!$P$2:$P$301,"Pass")/COUNTA(Data!$A$2:$A$301) -> 0.89 | E43: =AVERAGE(Data!$D$2:$D$301) -> 11.287333 | F43: =AVERAGE(Data!$E$2:$E$301) -> 84.583333
A45: 6. Performance by parental education
A46: Parental Education | B46: Students | C46: Avg score | D46: Pass rate | E46: Avg study hrs/wk | F46: Avg attendance %
A47: Basic | B47: =COUNTIFS(Data!$F$2:$F$301,$A47) -> 93 | C47: =IFERROR(AVERAGEIFS(Data!$N$2:$N$301,Data!$F$2:$F$301,$A47),0) -> 58.703226 | D47: =IFERROR(COUNTIFS(Data!$F$2:$F$301,$A47,Data!$P$2:$P$301,"Pass")/B47,0) -> 0.78494624 | E47: =IFERROR(AVERAGEIFS(Data!$D$2:$D$301,Data!$F$2:$F$301,$A47),0) -> 11.001075 | F47: =IFERROR(AVERAGEIFS(Data!$E$2:$E$301,Data!$F$2:$F$301,$A47),0) -> 83.817204
...

Sheet Top_Bottom
A1: Top 10 & Bottom 10 Students
A2: Pulled from the Rank column on the Data sheet (ties broken by row order).
A4: Top 10
A5: Rank | B5: Student ID | C5: Grade level | D5: Average | E5: Study hrs/wk | F5: Attendance % | G5: At risk
A6: 1 | B6: =INDEX(Data!$A$2:$A$301,MATCH($A6,Data!$T$2:$T$301,0)) -> S067 | C6: =INDEX(Data!$C$2:$C$301,MATCH($A6,Data!$T$2:$T$301,0)) -> Grade 12 | D6: =INDEX(Data!$N$2:$N$301,MATCH($A6,Data!$T$2:$T$301,0)) -> 88.6 | E6: =INDEX(Data!$D$2:$D$301,MATCH($A6,Data!$T$2:$T$301,0)) -> 18 | F6: =INDEX(Data!$E$2:$E$301,MATCH($A6,Data!$T$2:$T$301,0)) -> 95 | G6: =INDEX(Data!$S$2:$S$301,MATCH($A6,Data!$T$2:$T$301,0)) -> No
A7: 2 | B7: =INDEX(Data!$A$2:$A$301,MATCH($A7,Data!$T$2:$T$301,0)) -> S121 | C7: =INDEX(Data!$C$2:$C$301,MATCH($A7,Data!$T$2:$T$301,0)) -> Grade 11 | D7: =INDEX(Data!$N$2:$N$301,MATCH($A7,Data!$T$2:$T$301,0)) -> 83.6 | E7: =INDEX(Data!$D$2:$D$301,MATCH($A7,Data!$T$2:$T$301,0)) -> 17.9 | F7: =INDEX(Data!$E$2:$E$301,MATCH($A7,Data!$T$2:$T$301,0)) -> 94 | G7: =INDEX(Data!$S$2:$S$301,MATCH($A7,Data!$T$2:$T$301,0)) -> No
A8: 3 | B8: =INDEX(Data!$A$2:$A$301,MATCH($A8,Data!$T$2:$T$301,0)) -> S259 | C8: =INDEX(Data!$C$2:$C$301,MATCH($A8,Data!$T$2:$T$301,0)) -> Grade 11 | D8: =INDEX(Data!$N$2:$N$301,MATCH($A8,Data!$T$2:$T$301,0)) -> 82.4 | E8: =INDEX(Data!$D$2:$D$301,MATCH($A8,Data!$T$2:$T$301,0)) -> 15 | F8: =INDEX(Data!$E$2:$E$301,MATCH($A8,Data!$T$2:$T$301,0)) -> 92 | G8: =INDEX(Data!$S$2:$S$301,MATCH($A8,Data!$T$2:$T$301,0)) -> No
A9: 4 | B9: =INDEX(Data!$A$2:$A$301,MATCH($A9,Data!$T$2:$T$301,0)) -> S072 | C9: =INDEX(Data!$C$2:$C$301,MATCH($A9,Data!$T$2:$T$301,0)) -> Grade 10 | D9: =INDEX(Data!$N$2:$N$301,MATCH($A9,Data!$T$2:$T$301,0)) -> 79.8 | E9: =INDEX(Data!$D$2:$D$301,MATCH($A9,Data!$T$2:$T$301,0)) -> 13.5 | F9: =INDEX(Data!$E$2:$E$301,MATCH($A9,Data!$T$2:$T$301,0)) -> 87 | G9: =INDEX(Data!$S$2:$S$301,MATCH($A9,Data!$T$2:$T$301,0)) -> No
A10: 5 | B10: =INDEX(Data!$A$2:$A$301,MATCH($A10,Data!$T$2:$T$301,0)) -> S224 | C10: =INDEX(Data!$C$2:$C$301,MATCH($A10,Data!$T$2:$T$301,0)) -> Grade 11 | D10: =INDEX(Data!$N$2:$N$301,MATCH($A10,Data!$T$2:$T$301,0)) -> 79 | E10: =INDEX(Data!$D$2:$D$301,MATCH($A10,Data!$T$2:$T$301,0)) -> 18.1 | F10: =INDEX(Data!$E$2:$E$301,MATCH($A10,Data!$T$2:$T$301,0)) -> 86 | G10: =INDEX(Data!$S$2:$S$301,MATCH($A10,Data!$T$2:$T$301,0)) -> No
A11: 6 | B11: =INDEX(Data!$A$2:$A$301,MATCH($A11,Data!$T$2:$T$301,0)) -> S249 | C11: =INDEX(Data!$C$2:$C$301,MATCH($A11,Data!$T$2:$T$301,0)) -> Grade 12 | D11: =INDEX(Data!$N$2:$N$301,MATCH($A11,Data!$T$2:$T$301,0)) -> 79 | E11: =INDEX(Data!$D$2:$D$301,MATCH($A11,Data!$T$2:$T$301,0)) -> 17.1 | F11: =INDEX(Data!$E$2:$E$301,MATCH($A11,Data!$T$2:$T$301,0)) -> 97 | G11: =INDEX(Data!$S$2:$S$301,MATCH($A11,Data!$T$2:$T$301,0)) -> No
A12: 7 | B12: =INDEX(Data!$A$2:$A$301,MATCH($A12,Data!$T$2:$T$301,0)) -> S170 | C12: =INDEX(Data!$C$2:$C$301,MATCH($A12,Data!$T$2:$T$301,0)) -> Grade 11 | D12: =INDEX(Data!$N$2:$N$301,MATCH($A12,Data!$T$2:$T$301,0)) -> 78.8 | E12: =INDEX(Data!$D$2:$D$301,MATCH($A12,Data!$T$2:$T$301,0)) -> 17.4 | F12: =INDEX(Data!$E$2:$E$301,MATCH($A12,Data!$T$2:$T$301,0)) -> 93 | G12: =INDEX(Data!$S$2:$S$301,MATCH($A12,Data!$T$2:$T$301,0)) -> No
A13: 8 | B13: =INDEX(Data!$A$2:$A$301,MATCH($A13,Data!$T$2:$T$301,0)) -> S238 | C13: =INDEX(Data!$C$2:$C$301,MATCH($A13,Data!$T$2:$T$301,0)) -> Grade 10 | D13: =INDEX(Data!$N$2:$N$301,MATCH($A13,Data!$T$2:$T$301,0)) -> 78.8 | E13: =INDEX(Data!$D$2:$D$301,MATCH($A13,Data!$T$2:$T$301,0)) -> 23.9 | F13: =INDEX(Data!$E$2:$E$301,MATCH($A13,Data!$T$2:$T$301,0)) -> 89 | G13: =INDEX(Data!$S$2:$S$301,MATCH($A13,Data!$T$2:$T$301,0)) -> No
A14: 9 | B14: =INDEX(Data!$A$2:$A$301,MATCH($A14,Data!$T$2:$T$301,0)) -> S143 | C14: =INDEX(Data!$C$2:$C$301,MATCH($A14,Data!$T$2:$T$301,0)) -> Grade 12 | D14: =INDEX(Data!$N$2:$N$301,MATCH($A14,Data!$T$2:$T$301,0)) -> 78.6 | E14: =INDEX(Data!$D$2:$D$301,MATCH($A14,Data!$T$2:$T$301,0)) -> 18.3 | F14: =INDEX(Data!$E$2:$E$301,MATCH($A14,Data!$T$2:$T$301,0)) -> 93 | G14: =INDEX(Data!$S$2:$S$301,MATCH($A14,Data!$T$2:$T$301,0)) -> No
A15: 10 | B15: =INDEX(Data!$A$2:$A$301,MATCH($A15,Data!$T$2:$T$301,0)) -> S169 | C15: =INDEX(Data!$C$2:$C$301,MATCH($A15,Data!$T$2:$T$301,0)) -> Grade 10 | D15: =INDEX(Data!$N$2:$N$301,MATCH($A15,Data!$T$2:$T$301,0)) -> 78.6 | E15: =INDEX(Data!$D$2:$D$301,MATCH($A15,Data!$T$2:$T$301,0)) -> 13.9 | F15: =INDEX(Data!$E$2:$E$301,MATCH($A15,Data!$T$2:$T$301,0)) -> 93 | G15: =INDEX(Data!$S$2:$S$301,MATCH($A15,Data!$T$2:$T$301,0)) -> No
A18: Bottom 10
A19: Rank | B19: Student ID | C19: Grade level | D19: Average | E19: Study hrs/wk | F19: Attendance % | G19: At risk
A20: =COUNT(Data!$N$2:$N$301)-9 -> 291 | B20: =INDEX(Data!$A$2:$A$301,MATCH($A20,Data!$T$2:$T$301,0)) -> S160 | C20: =INDEX(Data!$C$2:$C$301,MATCH($A20,Data!$T$2:$T$301,0)) -> Grade 11 | D20: =INDEX(Data!$N$2:$N$301,MATCH($A20,Data!$T$2:$T$301,0)) -> 43.8 | E20: =INDEX(Data!$D$2:$D$301,MATCH($A20,Data!$T$2:$T$301,0)) -> 8.2 | F20: =INDEX(Data!$E$2:$E$301,MATCH($A20,Data!$T$2:$T$301,0)) -> 73 | G20: =INDEX(Data!$S$2:$S$301,MATCH($A20,Data!$T$2:$T$301,0)) -> Yes
A21: =COUNT(Data!$N$2:$N$301)-8 -> 292 | B21: =INDEX(Data!$A$2:$A$301,MATCH($A21,Data!$T$2:$T$301,0)) -> S244 | C21: =INDEX(Data!$C$2:$C$301,MATCH($A21,Data!$T$2:$T$301,0)) -> Grade 12 | D21: =INDEX(Data!$N$2:$N$301,MATCH($A21,Data!$T$2:$T$301,0)) -> 43.8 | E21: =INDEX(Data!$D$2:$D$301,MATCH($A21,Data!$T$2:$T$301,0)) -> 1 | F21: =INDEX(Data!$E$2:$E$301,MATCH($A21,Data!$T$2:$T$301,0)) -> 85 | G21: =INDEX(Data!$S$2:$S$301,MATCH($A21,Data!$T$2:$T$301,0)) -> Yes
A22: =COUNT(Data!$N$2:$N$301)-7 -> 293 | B22: =INDEX(Data!$A$2:$A$301,MATCH($A22,Data!$T$2:$T$301,0)) -> S196 | C22: =INDEX(Data!$C$2:$C$301,MATCH($A22,Data!$T$2:$T$301,0)) -> Grade 11 | D22: =INDEX(Data!$N$2:$N$301,MATCH($A22,Data!$T$2:$T$301,0)) -> 43.4 | E22: =INDEX(Data!$D$2:$D$301,MATCH($A22,Data!$T$2:$T$301,0)) -> 4.2 | F22: =INDEX(Data!$E$2:$E$301,MATCH($A22,Data!$T$2:$T$301,0)) -> 75 | G22: =INDEX(Data!$S$2:$S$301,MATCH($A22,Data!$T$2:$T$301,0)) -> Yes
A23: =COUNT(Data!$N$2:$N$301)-6 -> 294 | B23: =INDEX(Data!$A$2:$A$301,MATCH($A23,Data!$T$2:$T$301,0)) -> S212 | C23: =INDEX(Data!$C$2:$C$301,MATCH($A23,Data!$T$2:$T$301,0)) -> Grade 12 | D23: =INDEX(Data!$N$2:$N$301,MATCH($A23,Data!$T$2:$T$301,0)) -> 42.6 | E23: =INDEX(Data!$D$2:$D$301,MATCH($A23,Data!$T$2:$T$301,0)) -> 4 | F23: =INDEX(Data!$E$2:$E$301,MATCH($A23,Data!$T$2:$T$301,0)) -> 81 | G23: =INDEX(Data!$S$2:$S$301,MATCH($A23,Data!$T$2:$T$301,0)) -> Yes
A24: =COUNT(Data!$N$2:$N$301)-5 -> 295 | B24: =INDEX(Data!$A$2:$A$301,MATCH($A24,Data!$T$2:$T$301,0)) -> S198 | C24: =INDEX(Data!$C$2:$C$301,MATCH($A24,Data!$T$2:$T$301,0)) -> Grade 11 | D24: =INDEX(Data!$N$2:$N$301,MATCH($A24,Data!$T$2:$T$301,0)) -> 42 | E24: =INDEX(Data!$D$2:$D$301,MATCH($A24,Data!$T$2:$T$301,0)) -> 3.2 | F24: =INDEX(Data!$E$2:$E$301,MATCH($A24,Data!$T$2:$T$301,0)) -> 74 | G24: =INDEX(Data!$S$2:$S$301,MATCH($A24,Data!$T$2:$T$301,0)) -> Yes
A25: =COUNT(Data!$N$2:$N$301)-4 -> 296 | B25: =INDEX(Data!$A$2:$A$301,MATCH($A25,Data!$T$2:$T$301,0)) -> S019 | C25: =INDEX(Data!$C$2:$C$301,MATCH($A25,Data!$T$2:$T$301,0)) -> Grade 10 | D25: =INDEX(Data!$N$2:$N$301,MATCH($A25,Data!$T$2:$T$301,0)) -> 41.4 | E25: =INDEX(Data!$D$2:$D$301,MATCH($A25,Data!$T$2:$T$301,0)) -> 10 | F25: =INDEX(Data!$E$2:$E$301,MATCH($A25,Data!$T$2:$T$301,0)) -> 76 | G25: =INDEX(Data!$S$2:$S$301,MATCH($A25,Data!$T$2:$T$301,0)) -> Yes
A26: =COUNT(Data!$N$2:$N$301)-3 -> 297 | B26: =INDEX(Data!$A$2:$A$301,MATCH($A26,Data!$T$2:$T$301,0)) -> S132 | C26: =INDEX(Data!$C$2:$C$301,MATCH($A26,Data!$T$2:$T$301,0)) -> Grade 12 | D26: =INDEX(Data!$N$2:$N$301,MATCH($A26,Data!$T$2:$T$301,0)) -> 37.4 | E26: =INDEX(Data!$D$2:$D$301,MATCH($A26,Data!$T$2:$T$301,0)) -> 5 | F26: =INDEX(Data!$E$2:$E$301,MATCH($A26,Data!$T$2:$T$301,0)) -> 78 | G26: =INDEX(Data!$S$2:$S$301,MATCH($A26,Data!$T$2:$T$301,0)) -> Yes
A27: =COUNT(Data!$N$2:$N$301)-2 -> 298 | B27: =INDEX(Data!$A$2:$A$301,MATCH($A27,Data!$T$2:$T$301,0)) -> S127 | C27: =INDEX(Data!$C$2:$C$301,MATCH($A27,Data!$T$2:$T$301,0)) -> Grade 10 | D27: =INDEX(Data!$N$2:$N$301,MATCH($A27,Data!$T$2:$T$301,0)) -> 37.2 | E27: =INDEX(Data!$D$2:$D$301,MATCH($A27,Data!$T$2:$T$301,0)) -> 1 | F27: =INDEX(Data!$E$2:$E$301,MATCH($A27,Data!$T$2:$T$301,0)) -> 74 | G27: =INDEX(Data!$S$2:$S$301,MATCH($A27,Data!$T$2:$T$301,0)) -> Yes
A28: =COUNT(Data!$N$2:$N$301)-1 -> 299 | B28: =INDEX(Data!$A$2:$A$301,MATCH($A28,Data!$T$2:$T$301,0)) -> S216 | C28: =INDEX(Data!$C$2:$C$301,MATCH($A28,Data!$T$2:$T$301,0)) -> Grade 10 | D28: =INDEX(Data!$N$2:$N$301,MATCH($A28,Data!$T$2:$T$301,0)) -> 36.6 | E28: =INDEX(Data!$D$2:$D$301,MATCH($A28,Data!$T$2:$T$301,0)) -> 3.9 | F28: =INDEX(Data!$E$2:$E$301,MATCH($A28,Data!$T$2:$T$301,0)) -> 90 | G28: =INDEX(Data!$S$2:$S$301,MATCH($A28,Data!$T$2:$T$301,0)) -> Yes
A29: =COUNT(Data!$N$2:$N$301)-0 -> 300 | B29: =INDEX(Data!$A$2:$A$301,MATCH($A29,Data!$T$2:$T$301,0)) -> S183 | C29: =INDEX(Data!$C$2:$C$301,MATCH($A29,Data!$T$2:$T$301,0)) -> Grade 11 | D29: =INDEX(Data!$N$2:$N$301,MATCH($A29,Data!$T$2:$T$301,0)) -> 32.2 | E29: =INDEX(Data!$D$2:$D$301,MATCH($A29,Data!$T$2:$T$301,0)) -> 1 | F29: =INDEX(Data!$E$2:$E$301,MATCH($A29,Data!$T$2:$T$301,0)) -> 73 | G29: =INDEX(Data!$S$2:$S$301,MATCH($A29,Data!$T$2:$T$301,0)) -> Yes

Sheet Data
A1: Student_ID | B1: Gender | C1: Grade_Level | D1: Study_Hours_Week | E1: Attendance_Pct | F1: Parental_Education | G1: Internet_Access | H1: Extracurricular | I1: Math | J1: English | K1: Science | L1: Social_Studies | M1: ICT | N1: Average | O1: Letter_Grade | P1: Result | Q1: Study_Band | R1: Attendance_Band | S1: At_Risk | T1: Rank
A2: S001 | B2: Male | C2: Grade 12 | D2: 16.8 | E2: 78 | F2: Secondary | G2: Yes | H2: No | I2: 70 | J2: 52 | K2: 51 | L2: 60 | M2: 65 | N2: =ROUND(AVERAGE(I2:M2),1) -> 59.6 | O2: =LOOKUP(N2,Settings!$A$10:$A$14,Settings!$B$10:$B$14) -> D | P2: =IF(N2>=Settings!$B$3,"Pass","Fail") -> Pass | Q2: =LOOKUP(D2,Settings!$A$19:$A$23,Settings!$B$19:$B$23) -> 15 to 19 hrs | R2: =LOOKUP(E2,Settings!$A$28:$A$31,Settings!$B$28:$B$31) -> 75 to 84% | S2: =IF(OR(N2<Settings!$B$4,E2<Settings!$B$5),"Yes","No") -> No | T2: =RANK(N2,$N$2:$N$301,0)+COUNTIF($N$2:N2,N2)-1 -> 180
A3: S002 | B3: Female | C3: Grade 10 | D3: 8.4 | E3: 79 | F3: Tertiary | G3: Yes | H3: No | I3: 60 | J3: 66 | K3: 67 | L3: 62 | M3: 67 | N3: =ROUND(AVERAGE(I3:M3),1) -> 64.4 | O3: =LOOKUP(N3,Settings!$A$10:$A$14,Settings!$B$10:$B$14) -> C | P3: =IF(N3>=Settings!$B$3,"Pass","Fail") -> Pass | Q3: =LOOKUP(D3,Settings!$A$19:$A$23,Settings!$B$19:$B$23) -> 5 to 9 hrs | R3: =LOOKUP(E3,Settings!$A$28:$A$31,Settings!$B$28:$B$31) -> 75 to 84% | S3: =IF(OR(N3<Settings!$B$4,E3<Settings!$B$5),"Yes","No") -> No | T3: =RANK(N3,$N$2:$N$301,0)+COUNTIF($N$2:N3,N3)-1 -> 122
A4: S003 | B4: Male | C4: Grade 11 | D4: 7.7 | E4: 80 | F4: Tertiary | G4: Yes | H4: No | I4: 59 | J4: 56 | K4: 61 | L4: 62 | M4: 53 | N4: =ROUND(AVERAGE(I4:M4),1) -> 58.2 | O4: =LOOKUP(N4,Settings!$A$10:$A$14,Settings!$B$10:$B$14) -> D | P4: =IF(N4>=Settings!$B$3,"Pass","Fail") -> Pass | Q4: =LOOKUP(D4,Settings!$A$19:$A$23,Settings!$B$19:$B$23) -> 5 to 9 hrs | R4: =LOOKUP(E4,Settings!$A$28:$A$31,Settings!$B$28:$B$31) -> 75 to 84% | S4: =IF(OR(N4<Settings!$B$4,E4<Settings!$B$5),"Yes","No") -> No | T4: =RANK(N4,$N$2:$N$301,0)+COUNTIF($N$2:N4,N4)-1 -> 194
A5: S004 | B5: Male | C5: Grade 11 | D5: 14.3 | E5: 78 | F5: Secondary | G5: Yes | H5: No | I5: 70 | J5: 55 | K5: 61 | L5: 75 | M5: 65 | N5: =ROUND(AVERAGE(I5:M5),1) -> 65.2 | O5: =LOOKUP(N5,Settings!$A$10:$A$14,Settings!$B$10:$B$14) -> C | P5: =IF(N5>=Settings!$B$3,"Pass","Fail") -> Pass | Q5: =LOOKUP(D5,Settings!$A$19:$A$23,Settings!$B$19:$B$23) -> 10 to 14 hrs | R5: =LOOKUP(E5,Settings!$A$28:$A$31,Settings!$B$28:$B$31) -> 75 to 84% | S5: =IF(OR(N5<Settings!$B$4,E5<Settings!$B$5),"Yes","No") -> No | T5: =RANK(N5,$N$2:$N$301,0)+COUNTIF($N$2:N5,N5)-1 -> 110
A6: S005 | B6: Female | C6: Grade 12 | D6: 16.9 | E6: 79 | F6: Tertiary | G6: No | H6: Yes | I6: 80 | J6: 66 | K6: 66 | L6: 65 | M6: 73 | N6: =ROUND(AVERAGE(I6:M6),1) -> 70 | O6: =LOOKUP(N6,Settings!$A$10:$A$14,Settings!$B$10:$B$14) -> B | P6: =IF(N6>=Settings!$B$3,"Pass","Fail") -> Pass | Q6: =LOOKUP(D6,Settings!$A$19:$A$23,Settings!$B$19:$B$23) -> 15 to 19 hrs | R6: =LOOKUP(E6,Settings!$A$28:$A$31,Settings!$B$28:$B$31) -> 75 to 84% | S6: =IF(OR(N6<Settings!$B$4,E6<Settings!$B$5),"Yes","No") -> No | T6: =RANK(N6,$N$2:$N$301,0)+COUNTIF($N$2:N6,N6)-1 -> 60
A7: S006 | B7: Male | C7: Grade 11 | D7: 12.2 | E7: 85 | F7: Tertiary | G7: Yes | H7: Yes | I7: 77 | J7: 65 | K7: 56 | L7: 69 | M7: 77 | N7: =ROUND(AVERAGE(I7:M7),1) -> 68.8 | O7: =LOOKUP(N7,Settings!$A$10:$A$14,Settings!$B$10:$B$14) -> C | P7: =IF(N7>=Settings!$B$3,"Pass","Fail") -> Pass | Q7: =LOOKUP(D7,Settings!$A$19:$A$23,Settings!$B$19:$B$23) -> 10 to 14 hrs | R7: =LOOKUP(E7,Settings!$A$28:$A$31,Settings!$B$28:$B$31) -> 85 to 94% | S7: =IF(OR(N7<Settings!$B$4,E7<Settings!$B$5),"Yes","No") -> No | T7: =RANK(N7,$N$2:$N$301,0)+COUNTIF($N$2:N7,N7)-1 -> 66
A8: S007 | B8: Male | C8: Grade 11 | D8: 5.6 | E8: 74 | F8: Tertiary | G8: Yes | H8: No | I8: 67 | J8: 54 | K8: 67 | L8: 42 | M8: 64 | N8: =ROUND(AVERAGE(I8:M8),1) -> 58.8 | O8: =LOOKUP(N8,Settings!$A$10:$A$14,Settings!$B$10:$B$14) -> D | P8: =IF(N8>=Settings!$B$3,"Pass","Fail") -> Pass | Q8: =LOOKUP(D8,Settings!$A$19:$A$23,Settings!$B$19:$B$23) -> 5 to 9 hrs | R8: =LOOKUP(E8,Settings!$A$28:$A$31,Settings!$B$28:$B$31) -> Below 75% | S8: =IF(OR(N8<Settings!$B$4,E8<Settings!$B$5),"Yes","No") -> Yes | T8: =RANK(N8,$N$2:$N$301,0)+COUNTIF($N$2:N8,N8)-1 -> 188
A9: S008 | B9: Male | C9: Grade 11 | D9: 5.2 | E9: 91 | F9: Basic | G9: Yes | H9: No | I9: 53 | J9: 50 | K9: 49 | L9: 53 | M9: 48 | N9: =ROUND(AVERAGE(I9:M9),1) -> 50.6 | O9: =LOOKUP(N9,Settings!$A$10:$A$14,Settings!$B$10:$B$14) -> D | P9: =IF(N9>=Settings!$B$3,"Pass","Fail") -> Pass | Q9: =LOOKUP(D9,Settings!$A$19:$A$23,Settings!$B$19:$B$23) -> 5 to 9 hrs | R9: =LOOKUP(E9,Settings!$A$28:$A$31,Settings!$B$28:$B$31) -> 85 to 94% | S9: =IF(OR(N9<Settings!$B$4,E9<Settings!$B$5),"Yes","No") -> Yes | T9: =RANK(N9,$N$2:$N$301,0)+COUNTIF($N$2:N9,N9)-1 -> 260
A10: S009 | B10: Female | C10: Grade 10 | D10: 4.9 | E10: 77 | F10: Secondary | G10: Yes | H10: Yes | I10: 48 | J10: 57 | K10: 66 | L10: 54 | M10: 57 | N10: =ROUND(AVERAGE(I10:M10),1) -> 56.4 | O10: =LOOKUP(N10,Settings!$A$10:$A$14,Settings!$B$10:$B$14) -> D | P10: =IF(N10>=Settings!$B$3,"Pass","Fail") -> Pass | Q10: =LOOKUP(D10,Settings!$A$19:$A$23,Settings!$B$19:$B$23) -> 0 to 4 hrs | R10: =LOOKUP(E10,Settings!$A$28:$A$31,Settings!$B$28:$B$31) -> 75 to 84% | S10: =IF(OR(N10<Settings!$B$4,E10<Settings!$B$5),"Yes","No") -> No | T10: =RANK(N10,$N$2:$N$301,0)+COUNTIF($N$2:N10,N10)-1 -> 209
A11: S010 | B11: Female | C11: Grade 10 | D11: 3.2 | E11: 100 | F11: Secondary | G11: Yes | H11: Yes | I11: 59 | J11: 54 | K11: 55 | L11: 52 | M11: 60 | N11: =ROUND(AVERAGE(I11:M11),1) -> 56 | O11: =LOOKUP(N11,Settings!$A$10:$A$14,Settings!$B$10:$B$14) -> D | P11: =IF(N11>=Settings!$B$3,"Pass","Fail") -> Pass | Q11: =LOOKUP(D11,Settings!$A$19:$A$23,Settings!$B$19:$B$23) -> 0 to 4 hrs | R11: =LOOKUP(E11,Settings!$A$28:$A$31,Settings!$B$28:$B$31) -> 95 to 100% | S11: =IF(OR(N11<Settings!$B$4,E11<Settings!$B$5),"Yes","No") -> No | T11: =RANK(N11,$N$2:$N$301,0)+COUNTIF($N$2:N11,N11)-1 -> 216
A12: S011 | B12: Female | C12: Grade 11 | D12: 12.5 | E12: 83 | F12: Secondary | G12: No | H12: No | I12: 50 | J12: 64 | K12: 63 | L12: 66 | M12: 60 | N12: =ROUND(AVERAGE(I12:M12),1) -> 60.6 | O12: =LOOKUP(N12,Settings!$A$10:$A$14,Settings!$B$10:$B$14) -> C | P12: =IF(N12>=Settings!$B$3,"Pass","Fail") -> Pass | Q12: =LOOKUP(D12,Settings!$A$19:$A$23,Settings!$B$19:$B$23) -> 10 to 14 hrs | R12: =LOOKUP(E12,Settings!$A$28:$A$31,Settings!$B$28:$B$31) -> 75 to 84% | S12: =IF(OR(N12<Settings!$B$4,E12<Settings!$B$5),"Yes","No") -> No | T12: =RANK(N12,$N$2:$N$301,0)+COUNTIF($N$2:N12,N12)-1 -> 168
A13: S012 | B13: Male | C13: Grade 11 | D13: 17.6 | E13: 88 | F13: Secondary | G13: No | H13: No | I13: 61 | J13: 68 | K13: 60 | L13: 59 | M13: 66 | N13: =ROUND(AVERAGE(I13:M13),1) -> 62.8 | O13: =LOOKUP(N13,Settings!$A$10:$A$14,Settings!$B$10:$B$14) -> C | P13: =IF(N13>=Settings!$B$3,"Pass","Fail") -> Pass | Q13: =LOOKUP(D13,Settings!$A$19:$A$23,Settings!$B$19:$B$23) -> 15 to 19 hrs | R13: =LOOKUP(E13,Settings!$A$28:$A$31,Settings!$B$28:$B$31) -> 85 to 94% | S13: =IF(OR(N13<Settings!$B$4,E13<Settings!$B$5),"Yes","No") -> No | T13: =RANK(N13,$N$2:$N$301,0)+COUNTIF($N$2:N13,N13)-1 -> 139
... A301: S300 | B301: Male | C301: Grade 11 | D301: 12.4 | E301: 77 | F301: Secondary | G301: No | H301: No | I301: 70 | J301: 75 | K301: 63 | L301: 61 | M301: 68 | N301: =ROUND(AVERAGE(I301:M301),1) -> 67.4 | O301: =LOOKUP(N301,Settings!$A$10:$A$14,Settings!$B$10:$B$14) -> C | P301: =IF(N301>=Settings!$B$3,"Pass","Fail") -> Pass | Q301: =LOOKUP(D301,Settings!$A$19:$A$23,Settings!$B$19:$B$23) -> 10 to 14 hrs | R301: =LOOKUP(E301,Settings!$A$28:$A$31,Settings!$B$28:$B$31) -> 75 to 84% | S301: =IF(OR(N301<Settings!$B$4,E301<Settings!$B$5),"Yes","No") -> No | T301: =RANK(N301,$N$2:$N$301,0)+COUNTIF($N$2:N301,N301)-1 -> 86

Sheet Settings
A1: Settings & Assumptions
A2: Blue text on yellow = editable input. Change a value and every sheet recalculates.
A3: Pass mark (student average >=) | B3: 50 | C3: Assumption: 50 is a common pass threshold; adjust to your school's rule.
A4: At-risk: average below | B4: 55 | C4: Assumption: students within 5 points of the pass mark need monitoring.
A5: At-risk: attendance % below | B5: 75 | C5: Assumption: below 75% attendance is a common early-warning level.
A8: Grade scale
A9: Min Average | B9: Letter Grade
A10: 0 | B10: F
A11: 50 | B11: D
A12: 60 | B12: C
A13: 70 | B13: B
A14: 80 | B14: A
A15: Assumption: simple A-F scale. Keep minimums in ascending order (used by LOOKUP).
A17: Study-hours bands
A18: Min hrs/week | B18: Band
A19: 0 | B19: 0 to 4 hrs
A20: 5 | B20: 5 to 9 hrs
A21: 10 | B21: 10 to 14 hrs
A22: 15 | B22: 15 to 19 hrs
A23: 20 | B23: 20+ hrs
A24: Bands are labels only; change minimums to re-bucket students.
A26: Attendance bands
A27: Min attendance % | B27: Band
A28: 0 | B28: Below 75%
A29: 75 | B29: 75 to 84%
A30: 85 | B30: 85 to 94%
A31: 95 | B31: 95 to 100%
A32: Bands are labels only; change minimums to re-bucket students.

Sheet Data_Dictionary
A1: Data Dictionary
A3: Column | B3: Type | C3: Description | D3: Source
A4: Student_ID | B4: Text | C4: Anonymous ID (S001-S300) | D4: Input
A5: Gender | B5: Text | C5: Female / Male | D5: Input
A6: Grade_Level | B6: Text | C6: Grade 10 / 11 / 12 | D6: Input
A7: Study_Hours_Week | B7: Number | C7: Self-reported study hours per week | D7: Input
A8: Attendance_Pct | B8: Number | C8: Percentage of school days attended (0-100) | D8: Input
A9: Parental_Education | B9: Text | C9: Highest parental education: Basic / Secondary / Tertiary | D9: Input
A10: Internet_Access | B10: Text | C10: Internet at home: Yes / No | D10: Input
A11: Extracurricular | B11: Text | C11: Takes part in clubs/sports: Yes / No | D11: Input
A12: Math, English, Science, Social_Studies, ICT | B12: Number | C12: Subject scores out of 100 | D12: Input
A13: Average | B13: Number | C13: Mean of the five subject scores, 1 decimal | D13: Formula
A14: Letter_Grade | B14: Text | C14: A-F from the grade scale on Settings | D14: Formula
... A19: Rank | B19: Number | C19: Unique rank by Average (1 = highest); ties broken by row order | D19: Formula
